Workbook

Sheet Assumptions
A1: Solace Life — Partner Revenue Model Assumptions
A2: Blue cells = inputs you can change
A4: SECTION A — USER GROWTH
A5: Assumption | B5: Value | C5: Notes
A6: Month 6 paid users | B6: 800 | C6: Source: Investor model — M6 milestone
A7: Year 1 paid users (Month 12) | B7: 2500 | C7: Source: Investor model — Y1 milestone
A8: Year 2 paid users (Month 24) | B8: 9500 | C8: Source: Investor model — Y2 milestone
A9: Annual referral engagement rate | B9: 0.25 | C9: Conservative; users are actively planning estates/legacy
A11: SECTION B — PARTNER TYPE LEAD DISTRIBUTION (must sum to 100%)
A12: Partner Type | B12: Lead Share % | C12: Notes
A13: Estate & Wills Lawyers | B13: 0.3 | C13: Highest intent — users actively creating wills/trusts
A14: Financial Planners | B14: 0.25 | C14: Estate & retirement planning alignment
A15: Realtors | B15: 0.25 | C15: Downsizing, estate property sales
A16: Senior Living | B16: 0.1 | C16: Care transition support
A17: CPA / Tax | B17: 0.1 | C17: Estate tax, trust administration
A18: TOTAL | B18: =SUM(B13:B17) -> 1 | C18: Must equal 100.0%
A20: SECTION C — CLOSE RATES BY PARTNER TYPE (Year 1 baseline, before scoring optimization)
A21: Partner Type | B21: Close Rate % | C21: Notes
A22: Estate Lawyers | B22: 0.4 | C22: Motivated buyers — high intent users
A23: Financial Planners | B23: 0.3 | C23: More competitive — users may already have advisors
A24: Realtors | B24: 0.35 | C24: Strong when user is actively downsizing
A25: Senior Living | B25: 0.25 | C25: Longer decision cycle
A26: CPA / Tax | B26: 0.35 | C26: High conversion when timing aligns with filing season
A28: SECTION D — CLOSE RATE IMPROVEMENT (Year 2, after partner scoring system in place)
A29: Close rate improvement applied to all partner types (absolute pp) | B29: 0.08 | C29: Partner scoring system routes leads to higher-performing partners
A31: SECTION E — FIXED FEE MODEL (flat fee per closed referral paid to Solace Life)
A32: Partner Type | B32: Fixed Fee ($) | C32: Basis Notes
A33: Estate Lawyers | B33: 600 | C33: Blended simple will $1,500–$5,000 × 15% referral fee
A34: Financial Planners | B34: 500 | C34: First engagement fee $2,000–$5,000 × ~15%
A35: Realtors | B35: 800 | C35: Flat fee per closed transaction
A36: Senior Living | B36: 400 | C36: Referral fee on first month placement
A37: CPA / Tax | B37: 300 | C37: Referral fee on first engagement
A39: SECTION F — PERCENTAGE FEE MODEL (% of partner's gross first engagement value)
A40: Partner Type | B40: Fee % | C40: Basis Notes
A41: Estate Lawyers | B41: 0.15 | C41: Avg first engagement $3,000 → ~$450 per close
A42: Financial Planners | B42: 0.12 | C42: Avg first year fee $3,500 → ~$420 per close
A43: Realtors | B43: 0.2 | C43: Avg gross commission $17,500 (Cdn $700K × 2.5%) → ~$3,500 per close
A44: Senior Living | B44: 0.15 | C44: Avg first month $4,500 → ~$675 per close
A45: CPA / Tax | B45: 0.15 | C45: Avg first engagement $1,500 → ~$225 per close
A47: SECTION G — AVERAGE ENGAGEMENT VALUES (reference basis for % fee calculation)
...

Sheet Partner Scoring System
A1: Solace Life Partner Scoring System
A2: Quarterly score determines referral volume allocation. Partners scored 0–100.
A4: SCORING CRITERIA & WEIGHTS
A5: Criterion | B5: Weight | C5: – | D5: Description
A6: Closing Ratio | B6: 40% | D6: Percentage of referred leads that result in a retained client
A7: Client Satisfaction | B7: 25% | D7: Average user rating after referral (1–5 stars, normalized to 100)
A8: Response Time | B8: 20% | D8: Speed of first contact: <24h=100, <48h=75, <72h=50, >72h=0
A9: Partnership Engagement | B9: 15% | D9: Profile completeness, training completion, active participation
A11: PARTNER TIER DEFINITIONS
A12: Tier | B12: Score Range | C12: Badge | D12: Referral Volume Allocation | E12: Description
A13: Platinum | B13: 90–100 | D13: 40% of available leads in region/category | E13: Top performers — priority routing
A14: Gold | B14: 75–89 | D14: 30% | E14: Strong performers — standard priority
A15: Silver | B15: 55–74 | D15: 20% | E15: Adequate — monitored, improvement encouraged
A16: Bronze | B16: 40–54 | D16: 10% | E16: Below expectations — formal improvement plan
A17: Suspended | B17: Below 40 | D17: 0% | E17: Paused pending review
A19: — QUARTERLY PARTNER SCORING CALCULATOR —
A20: Partner Name: | C20: Enter partner company or individual name
A21: Closing Ratio (enter as %): | C21: E.g. enter 0.40 for 40% close rate
A22: Client Satisfaction (1.0–5.0): | C22: Rating on 1–5 star scale
A23: Response Time Score (0–100): | C23: Use scoring guide: <24h=100, <48h=75, <72h=50, >72h=0
A24: Partnership Engagement (0–100): | C24: Composite: profile, training, participation
A26: CALCULATED OUTPUTS
A27: Closing Ratio Score (0–100): | B27: =IF(B21="","",B21*100) | C27: Close rate × 100 (e.g. 40% → score of 40)
A28: Satisfaction Score Normalized (0–100): | B28: =IF(B22="","",(B22-1)/4*100) | C28: (Stars − 1) / 4 × 100 (e.g. 4.5 stars → 87.5)
A29: Weighted Score (0–100): | B29: =IF(B27="","",B27*0.4+B28*0.25+B23*0.2+B24*0.15) | C29: Weighted: Close×40% + Satisfaction×25% + Response×20% + Engagement×15%
A30: Partner Tier: | B30: =IF(B29="","",IF(B29>=90,"Platinum",IF(B29>=75,"Gold",IF(B29>=55,"Silver",IF(B29>=40,"Bronze","Suspended"))))) | C30: Platinum ≥90 | Gold ≥75 | Silver ≥55 | Bronze ≥40 | Suspended <40
A31: Referral Volume Allocation: | B31: =IF(B30="","",IF(B30="Platinum","40%",IF(B30="Gold","30%",IF(B30="Silver","20%",IF(B30="Bronze","10%","0%"))))) | C31: % of available leads in partner's region/category
A32: Quarterly Action Required: | B32: =IF(B30="","",IF(OR(B30="Platinum",B30="Gold"),"No action needed",IF(B30="Silver","Schedule quarterly check-in",IF(B30="Bronze","Improvement plan required","Partnership review meeting required")))) | C32: Triggered automatically based on tier result

Sheet Fixed Fee Projections
A1: Partner Revenue Projections — Fixed Fee Model
A2: Flat fee paid to Solace Life per closed referral, regardless of deal size
D4: LEADS GENERATED | I4: CLOSED DEALS | N4: FIXED FEE REVENUE
A5: Period | B5: Paid Users | C5: Annual Leads | D5: Estate Lawyers | E5: Fin. Planners | F5: Realtors | G5: Senior Living | H5: CPA / Tax | I5: Estate Lawyers | J5: Fin. Planners | K5: Realtors | L5: Senior Living | M5: CPA / Tax | N5: Estate Lawyers | O5: Fin. Planners | P5: Realtors | Q5: Senior Living | R5: CPA / Tax | S5: TOTAL REVENUE
A6: Month 6 | B6: =Assumptions!$B$6 -> 800 | C6: =SUM(D6:H6) -> 100 | D6: =Assumptions!$B$6*Assumptions!$B$9*Assumptions!$B$13*(6/12) -> 30 | E6: =Assumptions!$B$6*Assumptions!$B$9*Assumptions!$B$14*(6/12) -> 25 | F6: =Assumptions!$B$6*Assumptions!$B$9*Assumptions!$B$15*(6/12) -> 25 | G6: =Assumptions!$B$6*Assumptions!$B$9*Assumptions!$B$16*(6/12) -> 10 | H6: =Assumptions!$B$6*Assumptions!$B$9*Assumptions!$B$17*(6/12) -> 10 | I6: =D6*Assumptions!$B$22 -> 12 | J6: =E6*Assumptions!$B$23 -> 7.5 | K6: =F6*Assumptions!$B$24 -> 8.75 | L6: =G6*Assumptions!$B$25 -> 2.5 | M6: =H6*Assumptions!$B$26 -> 3.5 | N6: =I6*Assumptions!$B$33 -> 7200 | O6: =J6*Assumptions!$B$34 -> 3750 | P6: =K6*Assumptions!$B$35 -> 7000 | Q6: =L6*Assumptions!$B$36 -> 1000 | R6: =M6*Assumptions!$B$37 -> 1050 | S6: =SUM(N6:R6) -> 20000
A7: Year 1 | B7: =Assumptions!$B$7 -> 2500 | C7: =SUM(D7:H7) -> 625 | D7: =Assumptions!$B$7*Assumptions!$B$9*Assumptions!$B$13*1 -> 187.5 | E7: =Assumptions!$B$7*Assumptions!$B$9*Assumptions!$B$14*1 -> 156.25 | F7: =Assumptions!$B$7*Assumptions!$B$9*Assumptions!$B$15*1 -> 156.25 | G7: =Assumptions!$B$7*Assumptions!$B$9*Assumptions!$B$16*1 -> 62.5 | H7: =Assumptions!$B$7*Assumptions!$B$9*Assumptions!$B$17*1 -> 62.5 | I7: =D7*Assumptions!$B$22 -> 75 | J7: =E7*Assumptions!$B$23 -> 46.875 | K7: =F7*Assumptions!$B$24 -> 54.6875 | L7: =G7*Assumptions!$B$25 -> 15.625 | M7: =H7*Assumptions!$B$26 -> 21.875 | N7: =I7*Assumptions!$B$33 -> 45000 | O7: =J7*Assumptions!$B$34 -> 23437.5 | P7: =K7*Assumptions!$B$35 -> 43750 | Q7: =L7*Assumptions!$B$36 -> 6250 | R7: =M7*Assumptions!$B$37 -> 6562.5 | S7: =SUM(N7:R7) -> 125000
A8: Year 2 | B8: =Assumptions!$B$8 -> 9500 | C8: =SUM(D8:H8) -> 2375 | D8: =Assumptions!$B$8*Assumptions!$B$9*Assumptions!$B$13*1 -> 712.5 | E8: =Assumptions!$B$8*Assumptions!$B$9*Assumptions!$B$14*1 -> 593.75 | F8: =Assumptions!$B$8*Assumptions!$B$9*Assumptions!$B$15*1 -> 593.75 | G8: =Assumptions!$B$8*Assumptions!$B$9*Assumptions!$B$16*1 -> 237.5 | H8: =Assumptions!$B$8*Assumptions!$B$9*Assumptions!$B$17*1 -> 237.5 | I8: =D8*(Assumptions!$B$22+Assumptions!$B$29) -> 342 | J8: =E8*(Assumptions!$B$23+Assumptions!$B$29) -> 225.625 | K8: =F8*(Assumptions!$B$24+Assumptions!$B$29) -> 255.3125 | L8: =G8*(Assumptions!$B$25+Assumptions!$B$29) -> 78.375 | M8: =H8*(Assumptions!$B$26+Assumptions!$B$29) -> 102.125 | N8: =I8*Assumptions!$B$33 -> 205200 | O8: =J8*Assumptions!$B$34 -> 112812.5 | P8: =K8*Assumptions!$B$35 -> 204250 | Q8: =L8*Assumptions!$B$36 -> 31350 | R8: =M8*Assumptions!$B$37 -> 30637.5 | S8: =SUM(N8:R8) -> 584250
A10: SUMMARY
A11: 6-Month Revenue Total | B11: =S6 -> 20000
A12: Year 1 Revenue Total | B12: =S7 -> 125000
A13: Year 2 Revenue Total | B13: =S8 -> 584250
A14: 2-Year Cumulative Revenue | B14: =S6+S7+S8 -> 729250
A15: Year 2 vs Year 1 Growth | B15: =(S8-S7)/S7 -> 3.674

Sheet Percentage Fee Projections
A1: Partner Revenue Projections — Percentage Fee Model
A2: Solace Life earns % of partner's gross first engagement value per closed referral
D4: LEADS GENERATED | I4: CLOSED DEALS | N4: PERCENTAGE FEE REVENUE
A5: Period | B5: Paid Users | C5: Annual Leads | D5: Estate Lawyers | E5: Fin. Planners | F5: Realtors | G5: Senior Living | H5: CPA / Tax | I5: Estate Lawyers | J5: Fin. Planners | K5: Realtors | L5: Senior Living | M5: CPA / Tax | N5: Estate Lawyers | O5: Fin. Planners | P5: Realtors | Q5: Senior Living | R5: CPA / Tax | S5: TOTAL REVENUE
A6: Month 6 | B6: =Assumptions!$B$6 -> 800 | C6: =SUM(D6:H6) -> 100 | D6: =Assumptions!$B$6*Assumptions!$B$9*Assumptions!$B$13*(6/12) -> 30 | E6: =Assumptions!$B$6*Assumptions!$B$9*Assumptions!$B$14*(6/12) -> 25 | F6: =Assumptions!$B$6*Assumptions!$B$9*Assumptions!$B$15*(6/12) -> 25 | G6: =Assumptions!$B$6*Assumptions!$B$9*Assumptions!$B$16*(6/12) -> 10 | H6: =Assumptions!$B$6*Assumptions!$B$9*Assumptions!$B$17*(6/12) -> 10 | I6: =D6*Assumptions!$B$22 -> 12 | J6: =E6*Assumptions!$B$23 -> 7.5 | K6: =F6*Assumptions!$B$24 -> 8.75 | L6: =G6*Assumptions!$B$25 -> 2.5 | M6: =H6*Assumptions!$B$26 -> 3.5 | N6: =I6*Assumptions!$B$41*Assumptions!$B$49 -> 5400 | O6: =J6*Assumptions!$B$42*Assumptions!$B$50 -> 3150 | P6: =K6*Assumptions!$B$43*Assumptions!$B$51 -> 30625 | Q6: =L6*Assumptions!$B$44*Assumptions!$B$52 -> 1687.5 | R6: =M6*Assumptions!$B$45*Assumptions!$B$53 -> 787.5 | S6: =SUM(N6:R6) -> 41650
A7: Year 1 | B7: =Assumptions!$B$7 -> 2500 | C7: =SUM(D7:H7) -> 625 | D7: =Assumptions!$B$7*Assumptions!$B$9*Assumptions!$B$13*1 -> 187.5 | E7: =Assumptions!$B$7*Assumptions!$B$9*Assumptions!$B$14*1 -> 156.25 | F7: =Assumptions!$B$7*Assumptions!$B$9*Assumptions!$B$15*1 -> 156.25 | G7: =Assumptions!$B$7*Assumptions!$B$9*Assumptions!$B$16*1 -> 62.5 | H7: =Assumptions!$B$7*Assumptions!$B$9*Assumptions!$B$17*1 -> 62.5 | I7: =D7*Assumptions!$B$22 -> 75 | J7: =E7*Assumptions!$B$23 -> 46.875 | K7: =F7*Assumptions!$B$24 -> 54.6875 | L7: =G7*Assumptions!$B$25 -> 15.625 | M7: =H7*Assumptions!$B$26 -> 21.875 | N7: =I7*Assumptions!$B$41*Assumptions!$B$49 -> 33750 | O7: =J7*Assumptions!$B$42*Assumptions!$B$50 -> 19687.5 | P7: =K7*Assumptions!$B$43*Assumptions!$B$51 -> 191406.25 | Q7: =L7*Assumptions!$B$44*Assumptions!$B$52 -> 10546.875 | R7: =M7*Assumptions!$B$45*Assumptions!$B$53 -> 4921.875 | S7: =SUM(N7:R7) -> 260312.5
A8: Year 2 | B8: =Assumptions!$B$8 -> 9500 | C8: =SUM(D8:H8) -> 2375 | D8: =Assumptions!$B$8*Assumptions!$B$9*Assumptions!$B$13*1 -> 712.5 | E8: =Assumptions!$B$8*Assumptions!$B$9*Assumptions!$B$14*1 -> 593.75 | F8: =Assumptions!$B$8*Assumptions!$B$9*Assumptions!$B$15*1 -> 593.75 | G8: =Assumptions!$B$8*Assumptions!$B$9*Assumptions!$B$16*1 -> 237.5 | H8: =Assumptions!$B$8*Assumptions!$B$9*Assumptions!$B$17*1 -> 237.5 | I8: =D8*(Assumptions!$B$22+Assumptions!$B$29) -> 342 | J8: =E8*(Assumptions!$B$23+Assumptions!$B$29) -> 225.625 | K8: =F8*(Assumptions!$B$24+Assumptions!$B$29) -> 255.3125 | L8: =G8*(Assumptions!$B$25+Assumptions!$B$29) -> 78.375 | M8: =H8*(Assumptions!$B$26+Assumptions!$B$29) -> 102.125 | N8: =I8*Assumptions!$B$41*Assumptions!$B$49 -> 153900 | O8: =J8*Assumptions!$B$42*Assumptions!$B$50 -> 94762.5 | P8: =K8*Assumptions!$B$43*Assumptions!$B$51 -> 893593.75 | Q8: =L8*Assumptions!$B$44*Assumptions!$B$52 -> 52903.125 | R8: =M8*Assumptions!$B$45*Assumptions!$B$53 -> 22978.125 | S8: =SUM(N8:R8) -> 1218137.5
A10: SUMMARY
A11: 6-Month Revenue Total | B11: =S6 -> 41650
A12: Year 1 Revenue Total | B12: =S7 -> 260312.5
A13: Year 2 Revenue Total | B13: =S8 -> 1218137.5
A14: 2-Year Cumulative Revenue | B14: =S6+S7+S8 -> 1520100
A15: Year 2 vs Year 1 Growth | B15: =(S8-S7)/S7 -> 3.6795198
A17: WHY THE PERCENTAGE MODEL OUTPERFORMS FIXED FEES
A18: 1. REALTOR LEVERAGE: Realtors generate ~$17,500 in gross commission per transaction. At 20%, Solace Life earns ~$3,500 per close vs. a $800 fixed fee — a 4.4× uplift on the single largest partner category.
A19: 2. SCALES WITH MARKET VALUE: As property values and professional fees grow over time, % revenue grows automatically — fixed fees do not.
A20: 3. ALIGNMENT OF INTERESTS: % fee aligns Solace Life with partner success. Higher-quality referrals = larger engagements = greater shared upside for both parties.

Sheet Model Comparison
A1: Fixed vs. Percentage Model — Summary Comparison
A2: All revenue figures from Fixed Fee Projections and Percentage Fee Projections sheets
A4: HEAD-TO-HEAD COMPARISON — ALL PERIODS
A5: Metric | B5: Month 6 | C5: Year 1 | D5: Year 2 | E5: 2-Year Cumulative
A6: Fixed Fee Revenue | B6: ='Fixed Fee Projections'!S6 -> 20000 | C6: ='Fixed Fee Projections'!S7 -> 125000 | D6: ='Fixed Fee Projections'!S8 -> 584250 | E6: ='Fixed Fee Projections'!S6+'Fixed Fee Projections'!S7+'Fixed Fee Projections'!S8 -> 729250
A7: Percentage Fee Revenue | B7: ='Percentage Fee Projections'!S6 -> 41650 | C7: ='Percentage Fee Projections'!S7 -> 260312.5 | D7: ='Percentage Fee Projections'!S8 -> 1218137.5 | E7: ='Percentage Fee Projections'!S6+'Percentage Fee Projections'!S7+'Percentage Fee Projections'!S8 -> 1520100
A8: Uplift from % Model ($) | B8: =B7-B6 -> 21650 | C8: =C7-C6 -> 135312.5 | D8: =D7-D6 -> 633887.5 | E8: =E7-E6 -> 790850
A9: Uplift from % Model (%) | B9: =IF(B6=0,"",( B7-B6)/B6) -> 1.0825 | C9: =IF(C6=0,"",( C7-C6)/C6) -> 1.0825 | D9: =IF(D6=0,"",( D7-D6)/D6) -> 1.0849593 | E9: =IF(E6=0,"",( E7-E6)/E6) -> 1.0844703
A11: REVENUE BREAKDOWN BY PARTNER TYPE — YEAR 2
A12: Partner Type | B12: Fixed Fee Revenue (Y2) | C12: Pct Fee Revenue (Y2) | D12: Fixed Fee Revenue ($) | E12: Pct Fee Revenue ($) | F12: Uplift ($) | G12: Uplift (%)
A13: Estate Lawyers | B13: ='Fixed Fee Projections'!N8 -> 205200 | C13: ='Percentage Fee Projections'!N8 -> 153900 | D13: =B13 -> 205200 | E13: =C13 -> 153900 | F13: =C13-B13 -> -51300 | G13: =IF(B13=0,"",(C13-B13)/B13) -> -0.25
A14: Fin. Planners | B14: ='Fixed Fee Projections'!O8 -> 112812.5 | C14: ='Percentage Fee Projections'!O8 -> 94762.5 | D14: =B14 -> 112812.5 | E14: =C14 -> 94762.5 | F14: =C14-B14 -> -18050 | G14: =IF(B14=0,"",(C14-B14)/B14) -> -0.16
A15: Realtors | B15: ='Fixed Fee Projections'!P8 -> 204250 | C15: ='Percentage Fee Projections'!P8 -> 893593.75 | D15: =B15 -> 204250 | E15: =C15 -> 893593.75 | F15: =C15-B15 -> 689343.75 | G15: =IF(B15=0,"",(C15-B15)/B15) -> 3.375
A16: Senior Living | B16: ='Fixed Fee Projections'!Q8 -> 31350 | C16: ='Percentage Fee Projections'!Q8 -> 52903.125 | D16: =B16 -> 31350 | E16: =C16 -> 52903.125 | F16: =C16-B16 -> 21553.125 | G16: =IF(B16=0,"",(C16-B16)/B16) -> 0.6875
A17: CPA / Tax | B17: ='Fixed Fee Projections'!R8 -> 30637.5 | C17: ='Percentage Fee Projections'!R8 -> 22978.125 | D17: =B17 -> 30637.5 | E17: =C17 -> 22978.125 | F17: =C17-B17 -> -7659.375 | G17: =IF(B17=0,"",(C17-B17)/B17) -> -0.25
A19: TOTAL | B19: =SUM(B14:B18) -> 379050 | C19: =SUM(C14:C18) -> 1064237.5 | D19: =SUM(D14:D18) -> 379050 | E19: =SUM(E14:E18) -> 1064237.5 | F19: =SUM(F14:F18) -> 685187.5 | G19: =IF(B19=0,"",(C19-B19)/B19) -> 1.8076441
A21: RECOMMENDATION
A22: RECOMMENDATION: The percentage-based model generates materially higher revenue at every stage, driven primarily by real estate transaction values. The fixed fee model provides certainty and simplicity but leaves significant value on the table. Recommended: Launch with percentage model, with a minimum floor (e.g., $300 minimum per referral regardless of deal size) to protect against edge cases.

Sheet User Survey
A1: SOLACE LIFE — PARTNER USER SURVEY
A2: Sent to users after each partner interaction · 1–5 Star Rating Scale · Results feed directly into partner composite scores
A4: SURVEY QUESTIONS
A5: # | B5: Survey Question (shown to Solace Life user) | C5: Scoring Criterion | D5: Weight | E5: 1 ★ (Lowest) | F5: 3 ★★★ (Mid) | G5: 5 ★★★★★ (Highest)
A6: Q1 | B6: How quickly did [Partner Name] respond to your initial inquiry? | C6: Response Time | D6: 20% | E6: No response / days later | F6: 24 hours | G6: Within hours
A7: Q2 | B7: How would you rate [Partner Name]'s communication throughout the process? | C7: Satisfaction | D7: 10% | E7: Unclear, unhelpful | F7: Adequate | G7: Clear and proactive
A8: Q3 | B8: Did [Partner Name] take time to understand your specific needs and situation? | C8: Satisfaction | D8: 15% | E8: Not at all | F8: Somewhat | G8: Fully understood
A9: Q4 | B9: Did you complete a transaction or service engagement with [Partner Name]? | C9: Closing Ratio | D9: 30% | E9: No — did not proceed | F9: Partial engagement | G9: Yes — completed
A10: Q5 | B10: Would you recommend [Partner Name] to another Solace Life member? | C10: Recommendation | D10: 25% | E10: Definitely not | F10: Maybe | G10: Absolutely
A11: Q6 | B11: Overall, how satisfied are you with your experience with [Partner Name]? | C11: Satisfaction | D11: — | E11: Very dissatisfied | F11: Neutral | G11: Extremely satisfied
B12: (Q6 averaged with Q2 & Q3 for Satisfaction criterion)
A14: SCORE CONVERSION
A15: Stars Awarded | B15: 1 ★ | C15: 2 ★★ | D15: 3 ★★★ | E15: 4 ★★★★ | F15: 5 ★★★★★
A16: Score (0–100) | B16: 0 | C16: 25 | D16: 50 | E16: 75 | F16: 100
A17: Formula: Score = (Stars − 1) ÷ 4 × 100 | Q4 (Transaction Completed): Yes = 100 pts, No = 0 pts
A19: SAMPLE COMPLETED SURVEY (Demo)
A20: Partner Name | B20: Harbour Wealth Planning
A21: Partner Type | B21: Financial Planner
A22: Solace User ID | B22: SL-8842 (anonymized in system)
A23: Date of Interaction | B23: May 12, 2026
A24: Q1 — Response Time | B24: ★★★★★ 5 stars
A25: Q2 — Communication | B25: ★★★★☆ 4 stars
A26: Q3 — Understood Needs | B26: ★★★★★ 5 stars
A27: Q4 — Transaction Complete | B27: Yes ✓ (counts as 100 pts)
A28: Q5 — Recommendation | B28: ★★★★★ 5 stars
A29: Q6 — Overall Satisfaction | B29: ★★★★★ 5 stars
A31: Calculated Composite Score | B31: 96.3 / 100 → Tier: Platinum

Sheet Partner Score Tracker
A1: SOLACE LIFE — PARTNER SCORE TRACKER
A2: Quarterly composite scores derived from user survey data · Blue cells = manual input · Black cells = auto-calculated
A4: TIER THRESHOLDS | B4: Platinum | C4: 85 – 100 | D4: Gold | E4: 70 – 84 | F4: Silver | G4: 55 – 69 | H4: Bronze | I4: 40 – 54 | J4: Suspended | K4: < 40
A5: Composite Score = (Transaction Rate × 30%) + (Avg Satisfaction Stars→100 × 25%) + (Response Time Stars→100 × 20%) + (Recommendation Rate × 25%)
A7: Q2 2026 — CURRENT QUARTER SCORES
A8: Partner Name | B8: Type | C8: Surveys This Qtr | D8: Q1 Response Time ★ | E8: Q2 Comm. ★ | F8: Q3 Needs ★ | G8: Q4 Transaction Rate % | H8: Q5 Recom. Rate % | I8: Q6 Overall ★ | J8: Composite Score | K8: Tier | L8: Prev Qtr Score | M8: Trend ▲▼
A9: Harbour Wealth Planning | B9: Financial Planner | C9: 14 | D9: 4.8 | E9: 4.7 | F9: 4.9 | G9: 86 | H9: 93 | I9: 4.8 | J9: =ROUND(G9*0.3 + (AVERAGE(E9,F9,I9)-1)/4*100*0.25 + (D9-1)/4*100*0.2 + H9*0.25, 1) -> 91.8 | K9: =IF(J9="","",IF(J9>=85,"Platinum",IF(J9>=70,"Gold",IF(J9>=55,"Silver",IF(J9>=40,"Bronze","Suspended"))))) -> Platinum | L9: 78 | M9: =IF(OR(J9="",L9=""),"—",IF(J9>L9,"▲",IF(J9<L9,"▼","—"))) -> ▲
A10: Clearview Tax Group | B10: Accountant / Tax | C10: 9 | D10: 4.3 | E10: 4.5 | F10: 4.4 | G10: 71 | H10: 78 | I10: 4.3 | J10: =ROUND(G10*0.3 + (AVERAGE(E10,F10,I10)-1)/4*100*0.25 + (D10-1)/4*100*0.2 + H10*0.25, 1) -> 78.6 | K10: =IF(J10="","",IF(J10>=85,"Platinum",IF(J10>=70,"Gold",IF(J10>=55,"Silver",IF(J10>=40,"Bronze","Suspended"))))) -> Gold | L10: 69.5 | M10: =IF(OR(J10="",L10=""),"—",IF(J10>L10,"▲",IF(J10<L10,"▼","—"))) -> ▲
A11: Diane Realty Group | B11: Realtor | C11: 22 | D11: 4.6 | E11: 4.8 | F11: 4.7 | G11: 82 | H11: 88 | I11: 4.7 | J11: =ROUND(G11*0.3 + (AVERAGE(E11,F11,I11)-1)/4*100*0.25 + (D11-1)/4*100*0.2 + H11*0.25, 1) -> 87.9 | K11: =IF(J11="","",IF(J11>=85,"Platinum",IF(J11>=70,"Gold",IF(J11>=55,"Silver",IF(J11>=40,"Bronze","Suspended"))))) -> Platinum | L11: 80 | M11: =IF(OR(J11="",L11=""),"—",IF(J11>L11,"▲",IF(J11<L11,"▼","—"))) -> ▲
A12: Sunrise Senior Living | B12: Senior Living | C12: 7 | D12: 3.9 | E12: 4.2 | F12: 4.1 | G12: 57 | H12: 71 | I12: 4 | J12: =ROUND(G12*0.3 + (AVERAGE(E12,F12,I12)-1)/4*100*0.25 + (D12-1)/4*100*0.2 + H12*0.25, 1) -> 68.7 | K12: =IF(J12="","",IF(J12>=85,"Platinum",IF(J12>=70,"Gold",IF(J12>=55,"Silver",IF(J12>=40,"Bronze","Suspended"))))) -> Silver | L12: 62 | M12: =IF(OR(J12="",L12=""),"—",IF(J12>L12,"▲",IF(J12<L12,"▼","—"))) -> ▲
A13: Pacific Estate Law | B13: Estate Lawyer | C13: 11 | D13: 4.1 | E13: 4 | F13: 4.3 | G13: 73 | H13: 75 | I13: 4.1 | J13: =ROUND(G13*0.3 + (AVERAGE(E13,F13,I13)-1)/4*100*0.25 + (D13-1)/4*100*0.2 + H13*0.25, 1) -> 75.7 | K13: =IF(J13="","",IF(J13>=85,"Platinum",IF(J13>=70,"Gold",IF(J13>=55,"Silver",IF(J13>=40,"Bronze","Suspended"))))) -> Gold | L13: 70 | M13: =IF(OR(J13="",L13=""),"—",IF(J13>L13,"▲",IF(J13<L13,"▼","—"))) -> ▲
J14: =IFERROR(IF(D14="","",ROUND(G14*0.3 + (AVERAGE(E14,F14,I14)-1)/4*100*0.25 + (D14-1)/4*100*0.2 + H14*0.25,1)),"") | K14: =IFERROR(IF(J14="","",IF(J14>=85,"Platinum",IF(J14>=70,"Gold",IF(J14>=55,"Silver",IF(J14>=40,"Bronze","Suspended")))))," ") | M14: =IFERROR(IF(OR(J14="",L14=""),"—",IF(J14>L14,"▲",IF(J14<L14,"▼","—"))),"—") -> —
J15: =IFERROR(IF(D15="","",ROUND(G15*0.3 + (AVERAGE(E15,F15,I15)-1)/4*100*0.25 + (D15-1)/4*100*0.2 + H15*0.25,1)),"") | K15: =IFERROR(IF(J15="","",IF(J15>=85,"Platinum",IF(J15>=70,"Gold",IF(J15>=55,"Silver",IF(J15>=40,"Bronze","Suspended")))))," ") | M15: =IFERROR(IF(OR(J15="",L15=""),"—",IF(J15>L15,"▲",IF(J15<L15,"▼","—"))),"—") -> —
J16: =IFERROR(IF(D16="","",ROUND(G16*0.3 + (AVERAGE(E16,F16,I16)-1)/4*100*0.25 + (D16-1)/4*100*0.2 + H16*0.25,1)),"") | K16: =IFERROR(IF(J16="","",IF(J16>=85,"Platinum",IF(J16>=70,"Gold",IF(J16>=55,"Silver",IF(J16>=40,"Bronze","Suspended")))))," ") | M16: =IFERROR(IF(OR(J16="",L16=""),"—",IF(J16>L16,"▲",IF(J16<L16,"▼","—"))),"—") -> —
J17: =IFERROR(IF(D17="","",ROUND(G17*0.3 + (AVERAGE(E17,F17,I17)-1)/4*100*0.25 + (D17-1)/4*100*0.2 + H17*0.25,1)),"") | K17: =IFERROR(IF(J17="","",IF(J17>=85,"Platinum",IF(J17>=70,"Gold",IF(J17>=55,"Silver",IF(J17>=40,"Bronze","Suspended")))))," ") | M17: =IFERROR(IF(OR(J17="",L17=""),"—",IF(J17>L17,"▲",IF(J17<L17,"▼","—"))),"—") -> —
J18: =IFERROR(IF(D18="","",ROUND(G18*0.3 + (AVERAGE(E18,F18,I18)-1)/4*100*0.25 + (D18-1)/4*100*0.2 + H18*0.25,1)),"") | K18: =IFERROR(IF(J18="","",IF(J18>=85,"Platinum",IF(J18>=70,"Gold",IF(J18>=55,"Silver",IF(J18>=40,"Bronze","Suspended")))))," ") | M18: =IFERROR(IF(OR(J18="",L18=""),"—",IF(J18>L18,"▲",IF(J18<L18,"▼","—"))),"—") -> —
A21: COMPOSITE SCORE FORMULA REFERENCE
A22: Transaction Rate (30%) | B22: Q4 — % of users who answered Yes to "Did you complete a transaction?" · Input as a whole number (e.g. 82 = 82%)
A23: Satisfaction (25%) | B23: Average of Q2 (Communication) + Q3 (Needs Understood) + Q6 (Overall) · Converted from 1–5 stars to 0–100 scale
A24: Response Time (20%) | B24: Q1 (How quickly did partner respond) · Converted from 1–5 stars to 0–100 scale using (Stars−1)÷4×100
A25: Recommendation Rate (25%) | B25: Q5 — % of users who rated 4 or 5 stars on "Would you recommend?" · Input as whole number (e.g. 88 = 88%)
