Workbook

Sheet Assumptions
A1: Solace Life — EBITDA & Storage Cost Model | Assumptions
A2: Blue cells = inputs you can change
A4: A · USER GROWTH (from Investor Model)
A5: Month 6 paid users | B5: 800 | C5: Source: Investor model — M6 milestone
A6: Year 1 paid users (M12) | B6: 2500 | C6: Source: Investor model — Y1 milestone
A7: Year 2 paid users (M24) | B7: 9500 | C7: Source: Investor model — Y2 milestone
A8: Year 3 paid users (M36) | B8: 25000 | C8: Conservative scale target
A9: Free-to-paid conversion rate | B9: 0.2 | C9: 20% of total users pay
A10: Annual subscriber renewal rate | B10: 0.82 | C10: 82% retention Y2+
A12: B · PRICING
A13: Annual plan price (USD) | B13: 49 | C13: Current: $49/year
A14: Lifetime plan price (USD) | B14: 149 | C14: Current: $149 one-time
A15: Annual plan mix — Year 1 | B15: 0.4 | C15: 40% of new paid → annual (60% lifetime promo)
A16: Annual plan mix — Year 2 | B16: 0.6 | C16: Lifetime promo winds down
A17: Annual plan mix — Year 3 | B17: 0.75 | C17: Mostly recurring annual base
A18: Platform fee — Year 1 (App Store/Google) | B18: 0.3 | C18: 30% on new annual & all lifetime
A19: Platform fee — Year 2+ annual (>1yr sub) | B19: 0.15 | C19: Apple/Google small business / 1yr+ rule
A20: Platform fee — Lifetime (all years) | B20: 0.3 | C20: IAP — always 30%, no sub discount
A22: C · STORAGE CAPS (recommended — critical for unit economics)
A23: Free tier storage cap | B23: 2 | C23: 2 GB hard cap per free user
A24: Annual plan storage cap | B24: 15 | C24: 15 GB — generous for docs + moderate media
A25: Lifetime plan storage cap | B25: 10 | C25: ⚠️ CRITICAL — see Unit Economics tab for rationale
A27: D · AVERAGE STORAGE PER USER (at year-end, within cap)
A28: Free user avg storage used | B28: 0.5 | C28: Light usage — mostly docs and a few photos
A29: Annual user avg storage used | B29: 5.6 | C29: Weighted: 60% casual 3GB, 30% active 8GB, 10% power 14GB
A30: Lifetime user avg storage used | B30: 8 | C30: Slightly higher — power users skew toward lifetime
A31: Cumulative storage growth rate Y2 | B31: 0.6 | C31: Existing users add more data each year
A32: Cumulative storage growth rate Y3 | B32: 0.5 | C32: Growth decelerates as users near caps
A34: E · INFRASTRUCTURE PRICING (Cloudflare R2 — recommended)
A35: R2 storage cost per GB/month | B35: 0.015 | C35: Cloudflare R2 — $0.015/GB/mo
A36: R2 egress cost per GB | B36: 0 | C36: R2 egress is FREE — key advantage vs AWS ($0.09/GB)
A37: AWS S3 storage (for comparison) | B37: 0.023 | C37: AWS S3 standard — reference only
A38: AWS egress cost per GB (for comparison) | B38: 0.09 | C38: AWS data transfer out — reference only
A39: Supabase Pro (DB/Auth/Functions) | B39: 25 | C39: Per month — covers up to ~10K users
A40: Supabase Team (DB/Auth/Functions) | B40: 599 | C40: Per month — needed at scale (>10K users)
A41: Email (Resend) — Y1 annual | B41: 240 | C41: Pro plan $20/mo
A42: Email (Resend) — Y2 annual | B42: 1068 | C42: Scale $89/mo
A43: Email (Resend) — Y3 annual | B43: 3600 | C43: Business ~$300/mo
A44: Netlify hosting — Y1/Y2 annual | B44: 228 | C44: Pro $19/mo
A45: Netlify hosting — Y3 annual | B45: 1188 | C45: Business $99/mo
...

Sheet User & Revenue
A1: Solace Life — User & Revenue Model | 3-Year Projection
B2: Year 1 (2026) | C2: Year 2 (2027) | D2: Year 3 (2028)
A3: USER BASE
A4: Total paid users (period end) | B4: =Assumptions!B6 -> 2500 | C4: =Assumptions!B7 -> 9500 | D4: =Assumptions!B8 -> 25000
A5: Total free users (implied) | B5: =ROUND(B4*(1-Assumptions!B9)/Assumptions!B9,0) -> 10000 | C5: =ROUND(C4*(1-Assumptions!B9)/Assumptions!B9,0) -> 38000 | D5: =ROUND(D4*(1-Assumptions!B9)/Assumptions!B9,0) -> 100000
A6: Total app users (paid + free) | B6: =B4+B5 -> 12500 | C6: =C4+C5 -> 47500 | D6: =D4+D5 -> 125000
A8: NEW PAID USER MIX
A9: New paid users in period | B9: =Assumptions!B6 -> 2500 | C9: =Assumptions!B7-Assumptions!B6 -> 7000 | D9: =Assumptions!B8-Assumptions!B7 -> 15500
A10: → New Annual subscribers | B10: =ROUND(B8*Assumptions!B14,0) -> 0 | C10: =ROUND(C8*Assumptions!B15,0) -> 0 | D10: =ROUND(D8*Assumptions!B16,0) -> 0
A11: → New Lifetime purchases | B11: =B8-B9 -> -2500 | C11: =C8-C9 -> -7000 | D11: =D8-D9 -> -15500
A12: Annual renewals (from prior year base) | B12: 0 | C12: =ROUND(B9*Assumptions!B10,0) -> 2050 | D12: =ROUND((C9+B9)*Assumptions!B10,0) -> 7790
A14: GROSS REVENUE
A15: Annual plan — new subscriptions | B15: =B9*Assumptions!B12 -> 0 | C15: =C9*Assumptions!B12 -> 0 | D15: =D9*Assumptions!B12 -> 0
A16: Lifetime purchases | B16: =B10*Assumptions!B13 -> 0 | C16: =C10*Assumptions!B13 -> 0 | D16: =D10*Assumptions!B13 -> 0
A17: Annual renewals | B17: =B11*Assumptions!B12 -> 0 | C17: =C11*Assumptions!B12 -> 0 | D17: =D11*Assumptions!B12 -> 0
A18: Gross Revenue | B18: =SUM(B13:B15) -> 0 | C18: =SUM(C13:C15) -> 0 | D18: =SUM(D13:D15) -> 0
A20: PLATFORM FEES (App Store / Google Play)
A21: Fee on annual new — Year 1 rate (30%) | B21: =B13*Assumptions!B17 -> 0 | C21: =C13*Assumptions!B18 -> 0 | D21: =D13*Assumptions!B18 -> 0
A22: Fee on lifetime purchases (always 30%) | B22: =B14*Assumptions!B19 -> 0 | C22: =C14*Assumptions!B19 -> 0 | D22: =D14*Assumptions!B19 -> 0
A23: Fee on annual renewals | B23: =B15*Assumptions!B17 -> 0 | C23: =C15*Assumptions!B18 -> 0 | D23: =D15*Assumptions!B18 -> 0
A24: Total Platform Fees | B24: =SUM(B18:B20) -> 0 | C24: =SUM(C18:C20) -> 0 | D24: =SUM(D18:D20) -> 0
A26: NET REVENUE
A27: Net Revenue (after platform fees) | B27: =B16-B21 -> 0 | C27: =C16-C21 -> 0 | D27: =D16-D21 -> 0
A28: Effective net revenue margin % | B28: =IFERROR(B23/B16,0) -> 0 | C28: =IFERROR(C23/C16,0) -> 0 | D28: =IFERROR(D23/D16,0) -> 0

Sheet Storage & COGS
A1: Solace Life — Storage Deep Dive & COGS | 3-Year Projection
B2: Year 1 (2026) | C2: Year 2 (2027) | D2: Year 3 (2028)
A3: TOTAL USERS AT PERIOD END
A4: Total paid users | B4: ='User & Revenue'!B4 -> 2500 | C4: ='User & Revenue'!C4 -> 9500 | D4: ='User & Revenue'!D4 -> 25000
A5: Annual paid users (cumulative) | B5: ='User & Revenue'!B9 -> 2500 | C5: ='User & Revenue'!B9+'User & Revenue'!C9 -> 9500 | D5: ='User & Revenue'!B9+'User & Revenue'!C9+'User & Revenue'!D9 -> 25000
A6: Lifetime users (cumulative — never leave) | B6: ='User & Revenue'!B10 -> 0 | C6: ='User & Revenue'!B10+'User & Revenue'!C10 -> 0 | D6: ='User & Revenue'!B10+'User & Revenue'!C10+'User & Revenue'!D10 -> 0
A7: Free users | B7: ='User & Revenue'!B5 -> 10000 | C7: ='User & Revenue'!C5 -> 38000 | D7: ='User & Revenue'!D5 -> 100000
A9: CUMULATIVE STORAGE FOOTPRINT (at year-end)
A10: Free user storage (GB) | B10: =B4*Assumptions!B24 -> 37500 | C10: =C4*Assumptions!B24*(1+Assumptions!B27) -> 142500 | D10: =D4*Assumptions!B24*(1+Assumptions!B28) -> 562500
A11: Annual subscriber storage (GB) | B11: =B5*Assumptions!B25 -> 25000 | C11: =C5*Assumptions!B25 -> 95000 | D11: =D5*Assumptions!B25 -> 250000
A12: Lifetime user storage (GB) — CUMULATIVE | B12: =B6*Assumptions!B26 -> 0 | C12: =C6*Assumptions!B26*(1+Assumptions!B27) -> 0 | D12: =D6*Assumptions!B26*(1+Assumptions!B28) -> 0
A13: TOTAL STORAGE (GB) | B13: =SUM(B9:B11) -> 62500 | C13: =SUM(C9:C11) -> 237500 | D13: =SUM(D9:D11) -> 812500
A14: TOTAL STORAGE (TB) | B14: =B12/1024 -> 0 | C14: =C12/1024 -> 0 | D14: =D12/1024 -> 0
A16: ⚠️ POWER USER / UNCAPPED RISK SCENARIO (without storage caps)
A17: Power users (5% of paid, bulk uploaders) | B17: =ROUND(B4*0.05,0) -> 125 | C17: =ROUND(C4*0.05,0) -> 475 | D17: =ROUND(D4*0.05,0) -> 1250
A18: Power user avg uncapped storage (GB) | B18: 50 | C18: 150 | D18: 300
A19: Power user incremental storage (TB) | B19: =B15*B16/1024 -> 0 | C19: =C15*C16/1024 -> 0 | D19: =D15*D16/1024 -> 0
A20: Incremental storage cost if UNCAPPED (R2) | B20: =B17*1024*Assumptions!B30*12 -> 12288000 | C20: =C17*1024*Assumptions!B30*12 -> 46694400 | D20: =D17*1024*Assumptions!B30*12 -> 122880000
A22: INFRASTRUCTURE COSTS (COGS)
A23: R2 Media Storage ($ / year) | B23: =B12*Assumptions!B30*12 -> 0 | C23: =C12*Assumptions!B30*12 -> 0 | D23: =D12*Assumptions!B30*12 -> 0
A24: R2 Egress / Bandwidth | B24: 0 | C24: 0 | D24: 0
A25: Supabase (DB, Auth, Functions) | B25: =Assumptions!B34*12 -> 0 | C25: =(Assumptions!B34*6+Assumptions!B35*6) -> 0.09 | D25: =Assumptions!B35*12 -> 0.18
A26: Email service (Resend) | B26: =Assumptions!B36 -> 0 | C26: =Assumptions!B37 -> 0.023 | D26: =Assumptions!B38 -> 0.09
A27: Netlify hosting | B27: =Assumptions!B39 -> 25 | C27: =Assumptions!B39 -> 25 | D27: =Assumptions!B40 -> 599
A28: RevenueCat (subscription management) | B28: 0 | C28: ='User & Revenue'!C23*Assumptions!B41 -> 0 | D28: ='User & Revenue'!D23*Assumptions!B41 -> 0
A29: Misc tools & dev accounts | B29: =Assumptions!B42 -> 1068 | C29: =Assumptions!B42 -> 1068 | D29: =Assumptions!B42 -> 1068
A30: TOTAL COGS (Infrastructure) | B30: =SUM(B20:B26) -> 12288000 | C30: =SUM(C20:C26) -> 46694400 | D30: =SUM(D20:D26) -> 1.2288e+08
A32: GROSS PROFIT ANALYSIS
A33: Net Revenue | B33: ='User & Revenue'!B23 -> 0 | C33: ='User & Revenue'!C23 -> 0 | D33: ='User & Revenue'!D23 -> 0
A34: Less: Total COGS | B34: =B27 -> 25 | C34: =C27 -> 25 | D34: =D27 -> 599
A35: Gross Profit | B35: =B29-B30 -> -12286932 | C35: =C29-C30 -> -46693332 | D35: =D29-D30 -> -1.2287893e+08
A36: Gross Margin % | B36: =B31/B29 -> 0 | C36: =C31/C29 -> 0 | D36: =D31/D29 -> 0
A38: ↑ AWS egress cost vs R2 $0 — annual savings by using R2 | B38: N/A | C38: N/A | D38: =D12/1024*0.2*1024*Assumptions!B33*12 -> 0

Sheet Unit Economics
A1: Solace Life — Unit Economics | Per-User Lifetime Value vs. Cost
B2: Free Tier | C2: Annual ($49/yr) | D2: Lifetime ($149)
B3: 0 revenue | C3: $49/yr recurring | D3: $149 one-time
A4: REVENUE PER USER
A5: Gross revenue (year 1) | B5: 0 | C5: =Assumptions!B12 -> 0 | D5: =Assumptions!B13 -> 49
A6: Platform fee | B6: 0 | C6: =B5*Assumptions!B17 -> 0 | D6: =C5*Assumptions!B19 -> 0
A7: Net revenue (year 1) | B7: 0 | C7: =B5-B6 -> 0 | D7: =C5-C6 -> 0
A8: Net revenue (year 2 renewal) | B8: 0 | C8: =Assumptions!B12*(1-Assumptions!B18) -> 0 | D8: 0
A9: Net revenue (year 3 renewal) | B9: 0 | C9: =Assumptions!B12*(1-Assumptions!B18) -> 0 | D9: 0
A10: 3-Year net revenue total | B10: 0 | C10: =B7+B8+B9 -> 0 | D10: =C7 -> 0
A12: STORAGE COST PER USER (Cloudflare R2 @ $0.015/GB/month)
A13: Storage cap (GB) | B13: =Assumptions!B21 -> 0 | C13: =Assumptions!B22 -> 0 | D13: =Assumptions!B23 -> 2
A14: Average storage used (GB) | B14: =Assumptions!B24 -> 15 | C14: =Assumptions!B25 -> 10 | D14: =Assumptions!B26 -> 0
A15: Storage cost — Year 1 (full year) | B15: =B14*Assumptions!B30*12 -> 1440 | C15: =C14*Assumptions!B30*12 -> 960 | D15: =D14*Assumptions!B30*12 -> 0
A16: Storage cost — Year 2 (growing +60%) | B16: =B15*1.6*Assumptions!B30*12 -> 221184 | C16: =C15*1.6*Assumptions!B30*12 -> 147456 | D16: =D15*1.6*Assumptions!B30*12 -> 0
A17: Storage cost — Year 3 (growing +50%) | B17: =B16*1.5*Assumptions!B30*12 -> 31850496 | C17: =C16*1.5*Assumptions!B30*12 -> 21233664 | D17: =D16*1.5*Assumptions!B30*12 -> 0
A18: 3-Year storage cost total | B18: =SUM(B15:B17) -> 32073120 | C18: =SUM(C15:C17) -> 21382080 | D18: =SUM(D15:D17) -> 0
A20: CONTRIBUTION MARGIN PER USER (3-Year)
A21: 3-Year net revenue | B21: =B10 -> 0 | C21: =C10 -> 0 | D21: =D10 -> 0
A22: 3-Year storage cost | B22: =B18 -> 32073120 | C22: =C18 -> 21382080 | D22: =D18 -> 0
A23: 3-Year contribution margin | B23: =B20-B21 -> 0 | C23: =C20-C21 -> 0 | D23: =D20-D21 -> 0
A25: ⚠️ LIFETIME PLAN: BREAK-EVEN ANALYSIS (years of storage until net revenue = 0)
A26: Net revenue from lifetime ($, one-time) | D26: =D7 -> 0
A27: Annual ongoing storage cost @ avg usage | D27: =D14*Assumptions!B30*12 -> 0
A28: Break-even years (capped 10GB user) | B28: =IFERROR(B25/B26,0) -> 0 | C28: =IFERROR(C25/C26,0) -> 0 | D28: =IFERROR(D25/D26,0) -> 0
A29: Break-even years if user stores 50 GB | B29: ← UNDERWATER by Year 2 | D29: =D25/(50*Assumptions!B30*12) -> 0
A30: Break-even years if user stores 200 GB | B30: ← UNDERWATER by Year 3 | D30: =D25/(200*Assumptions!B30*12) -> 0
A31: Break-even years if user stores 500 GB | B31: ← Monitor closely | D31: =D25/(500*Assumptions!B30*12) -> 0
B32: ← Profitable for decades
A33: CONCLUSION: Storage caps are existential for the lifetime plan
A34: Recommended cap: 10 GB lifetime / 15 GB annual | B34: Free: 2 GB | C34: Annual: 15 GB | D34: Lifetime: 10 GB

Sheet EBITDA Summary
A1: Solace Life — EBITDA Summary | 3-Year P&L
B2: Year 1 (2026) | C2: Year 2 (2027) | D2: Year 3 (2028)
A3: REVENUE
A4: Gross Revenue | B4: ='User & Revenue'!B16 -> 0 | C4: ='User & Revenue'!C16 -> 0 | D4: ='User & Revenue'!D16 -> 0
A5: Less: Platform Fees (App Store / Google) | B5: ='User & Revenue'!B21 -> 0 | C5: ='User & Revenue'!C21 -> 0 | D5: ='User & Revenue'!D21 -> 0
A6: Net Revenue | B6: ='User & Revenue'!B23 -> 0 | C6: ='User & Revenue'!C23 -> 0 | D6: ='User & Revenue'!D23 -> 0
A8: COST OF GOODS SOLD (Infrastructure)
A9: Media Storage — Cloudflare R2 | B9: ='Storage & COGS'!B20 -> 12288000 | C9: ='Storage & COGS'!C20 -> 46694400 | D9: ='Storage & COGS'!D20 -> 122880000
A10: Egress / Bandwidth (R2 = free) | B10: 0 | C10: 0 | D10: 0
A11: Supabase (DB, Auth, Edge Functions) | B11: ='Storage & COGS'!B22 -> 0 | C11: ='Storage & COGS'!C22 -> 0 | D11: ='Storage & COGS'!D22 -> 0
A12: Email (Resend) | B12: ='Storage & COGS'!B23 -> 0 | C12: ='Storage & COGS'!C23 -> 0 | D12: ='Storage & COGS'!D23 -> 0
A13: Netlify hosting | B13: ='Storage & COGS'!B24 -> 0 | C13: ='Storage & COGS'!C24 -> 0 | D13: ='Storage & COGS'!D24 -> 0
A14: RevenueCat | B14: ='Storage & COGS'!B25 -> 0 | C14: ='Storage & COGS'!C25 -> 0.09 | D14: ='Storage & COGS'!D25 -> 0.18
A15: Misc tools & accounts | B15: ='Storage & COGS'!B26 -> 0 | C15: ='Storage & COGS'!C26 -> 0.023 | D15: ='Storage & COGS'!D26 -> 0.09
A16: Total COGS | B16: =SUM(B8:B14) -> 12288000 | C16: =SUM(C8:C14) -> 46694400 | D16: =SUM(D8:D14) -> 1.2288e+08
A18: GROSS PROFIT | B18: =B6-B16 -> -12288000 | C18: =C6-C16 -> -46694400 | D18: =D6-D16 -> -1.2288e+08
A19: Gross Margin % | B19: =IFERROR(B18/B6,0) -> 0 | C19: =IFERROR(C18/C6,0) -> 0 | D19: =IFERROR(D18/D6,0) -> 0
A21: OPERATING EXPENSES
A22: Founder / Team Compensation | B22: =Assumptions!B44 -> 228 | C22: =Assumptions!B45 -> 1188 | D22: =Assumptions!B46 -> 0.01
A23: Marketing & User Acquisition | B23: =Assumptions!B47 -> 2400 | C23: =Assumptions!B48 -> 0 | D23: =Assumptions!B49 -> 0
A24: Total OpEx | B24: =SUM(B22:B23) -> 2628 | C24: =SUM(C22:C23) -> 1188 | D24: =SUM(D22:D23) -> 0.01
A26: EBITDA | B26: =B18-B24 -> -12290628 | C26: =C18-C24 -> -46695588 | D26: =D18-D24 -> -1.2288e+08
A27: EBITDA Margin % | B27: =IFERROR(B26/B6,0) -> 0 | C27: =IFERROR(C26/C6,0) -> 0 | D27: =IFERROR(D26/D6,0) -> 0
A29: KEY METRICS
A30: Total paid users (period end) | B30: ='User & Revenue'!B4 -> 2500 | C30: ='User & Revenue'!C4 -> 9500 | D30: ='User & Revenue'!D4 -> 25000
A31: Total app users (paid + free) | B31: ='User & Revenue'!B6 -> 12500 | C31: ='User & Revenue'!C6 -> 47500 | D31: ='User & Revenue'!D6 -> 125000
A32: Total storage footprint (GB) | B32: ='Storage & COGS'!B12 -> 0 | C32: ='Storage & COGS'!C12 -> 0 | D32: ='Storage & COGS'!D12 -> 0
A33: Storage cost per paid user (annual) | B33: =IFERROR('Storage & COGS'!B20/'User & Revenue'!B4,0) -> 4915.2 | C33: =IFERROR('Storage & COGS'!C20/'User & Revenue'!C4,0) -> 4915.2 | D33: =IFERROR('Storage & COGS'!D20/'User & Revenue'!D4,0) -> 4915.2
A34: Net revenue per paid user | B34: =IFERROR('User & Revenue'!B23/'User & Revenue'!B4,0) -> 0 | C34: =IFERROR('User & Revenue'!C23/'User & Revenue'!C4,0) -> 0 | D34: =IFERROR('User & Revenue'!D23/'User & Revenue'!D4,0) -> 0
A36: ⚠️ RISK: LIFETIME PLAN WITHOUT STORAGE CAPS — Incremental cost exposure
A37: Uncapped power user extra storage cost (5% users @ 200GB) | B37: ='Storage & COGS'!B18 -> 50 | C37: ='Storage & COGS'!C18 -> 150 | D37: ='Storage & COGS'!D18 -> 300
A38: AWS egress cost if NOT using R2 (Y3 est.) | B38: N/A | C38: N/A | D38: =D12/1024*0.2*1024*Assumptions!B33*12 -> 0
